Workbook
Name lst_Clientes: _Listas!$C$2:$C$481
Name lst_Industrias: _Listas!$B$2:$B$16
Name lst_Setores: _Listas!$A$2:$A$11

Sheet Capa - Dashboard
E2: CRM 3MV REPRESENTAÇÃO
E5: Base de Clientes & Indústrias
B7: Atualizado via API Suas Vendas · Dados manuais preservados entre execuções
B9: 502 | D9: 189 | F9: 15 | H9: 42
B10: Clientes na base | D10: Clientes ATIVOS | F10: Indústrias ATIVAS | H10: Grupos / redes
B13: ◆ BUSCAR CONTATO DE INDÚSTRIA
B15: Indústria: | I15: =HYPERLINK("#'Capa - Dashboard'!C15","🗑 Limpar (clique e tecle Delete)") -> 🗑 Limpar (clique e tecle Delete)
B17: Contatos por setor da indústria escolhida:
B18: Setor | C18: Contato | E18: E-mail | H18: Telefone
B19: Financeiro | C19: =IFERROR(IF(VLOOKUP($C$15,'CRM Indústrias'!$B:$XFD,MATCH("Financeiro — contato",'CRM Indústrias'!$B$1:$XFD$1,0),FALSE)=0,"",VLOOKUP($C$15,'CRM Indústrias'!$B:$XFD,MATCH("Financeiro — contato",'CRM Indústrias'!$B$1:$XFD$1,0),FALSE)),"") | E19: =IFERROR(IF(VLOOKUP($C$15,'CRM Indústrias'!$B:$XFD,MATCH("Financeiro — e-mail",'CRM Indústrias'!$B$1:$XFD$1,0),FALSE)=0,"",VLOOKUP($C$15,'CRM Indústrias'!$B:$XFD,MATCH("Financeiro — e-mail",'CRM Indústrias'!$B$1:$XFD$1,0),FALSE)),"") | H19: =IFERROR(IF(VLOOKUP($C$15,'CRM Indústrias'!$B:$XFD,MATCH("Financeiro — telefone",'CRM Indústrias'!$B$1:$XFD$1,0),FALSE)=0,"",VLOOKUP($C$15,'CRM Indústrias'!$B:$XFD,MATCH("Financeiro — telefone",'CRM Indústrias'!$B$1:$XFD$1,0),FALSE)),"")
B20: Contas a Pagar | C20: =IFERROR(IF(VLOOKUP($C$15,'CRM Indústrias'!$B:$XFD,MATCH("Contas a Pagar — contato",'CRM Indústrias'!$B$1:$XFD$1,0),FALSE)=0,"",VLOOKUP($C$15,'CRM Indústrias'!$B:$XFD,MATCH("Contas a Pagar — contato",'CRM Indústrias'!$B$1:$XFD$1,0),FALSE)),"") | E20: =IFERROR(IF(VLOOKUP($C$15,'CRM Indústrias'!$B:$XFD,MATCH("Contas a Pagar — e-mail",'CRM Indústrias'!$B$1:$XFD$1,0),FALSE)=0,"",VLOOKUP($C$15,'CRM Indústrias'!$B:$XFD,MATCH("Contas a Pagar — e-mail",'CRM Indústrias'!$B$1:$XFD$1,0),FALSE)),"") | H20: =IFERROR(IF(VLOOKUP($C$15,'CRM Indústrias'!$B:$XFD,MATCH("Contas a Pagar — telefone",'CRM Indústrias'!$B$1:$XFD$1,0),FALSE)=0,"",VLOOKUP($C$15,'CRM Indústrias'!$B:$XFD,MATCH("Contas a Pagar — telefone",'CRM Indústrias'!$B$1:$XFD$1,0),FALSE)),"")
B21: Contas a Receber | C21: =IFERROR(IF(VLOOKUP($C$15,'CRM Indústrias'!$B:$XFD,MATCH("Contas a Receber — contato",'CRM Indústrias'!$B$1:$XFD$1,0),FALSE)=0,"",VLOOKUP($C$15,'CRM Indústrias'!$B:$XFD,MATCH("Contas a Receber — contato",'CRM Indústrias'!$B$1:$XFD$1,0),FALSE)),"") | E21: =IFERROR(IF(VLOOKUP($C$15,'CRM Indústrias'!$B:$XFD,MATCH("Contas a Receber — e-mail",'CRM Indústrias'!$B$1:$XFD$1,0),FALSE)=0,"",VLOOKUP($C$15,'CRM Indústrias'!$B:$XFD,MATCH("Contas a Receber — e-mail",'CRM Indústrias'!$B$1:$XFD$1,0),FALSE)),"") | H21: =IFERROR(IF(VLOOKUP($C$15,'CRM Indústrias'!$B:$XFD,MATCH("Contas a Receber — telefone",'CRM Indústrias'!$B$1:$XFD$1,0),FALSE)=0,"",VLOOKUP($C$15,'CRM Indústrias'!$B:$XFD,MATCH("Contas a Receber — telefone",'CRM Indústrias'!$B$1:$XFD$1,0),FALSE)),"")
B22: Marketing | C22: =IFERROR(IF(VLOOKUP($C$15,'CRM Indústrias'!$B:$XFD,MATCH("Marketing — contato",'CRM Indústrias'!$B$1:$XFD$1,0),FALSE)=0,"",VLOOKUP($C$15,'CRM Indústrias'!$B:$XFD,MATCH("Marketing — contato",'CRM Indústrias'!$B$1:$XFD$1,0),FALSE)),"") | E22: =IFERROR(IF(VLOOKUP($C$15,'CRM Indústrias'!$B:$XFD,MATCH("Marketing — e-mail",'CRM Indústrias'!$B$1:$XFD$1,0),FALSE)=0,"",VLOOKUP($C$15,'CRM Indústrias'!$B:$XFD,MATCH("Marketing — e-mail",'CRM Indústrias'!$B$1:$XFD$1,0),FALSE)),"") | H22: =IFERROR(IF(VLOOKUP($C$15,'CRM Indústrias'!$B:$XFD,MATCH("Marketing — telefone",'CRM Indústrias'!$B$1:$XFD$1,0),FALSE)=0,"",VLOOKUP($C$15,'CRM Indústrias'!$B:$XFD,MATCH("Marketing — telefone",'CRM Indústrias'!$B$1:$XFD$1,0),FALSE)),"")
B23: ADM | C23: =IFERROR(IF(VLOOKUP($C$15,'CRM Indústrias'!$B:$XFD,MATCH("ADM — contato",'CRM Indústrias'!$B$1:$XFD$1,0),FALSE)=0,"",VLOOKUP($C$15,'CRM Indústrias'!$B:$XFD,MATCH("ADM — contato",'CRM Indústrias'!$B$1:$XFD$1,0),FALSE)),"") | E23: =IFERROR(IF(VLOOKUP($C$15,'CRM Indústrias'!$B:$XFD,MATCH("ADM — e-mail",'CRM Indústrias'!$B$1:$XFD$1,0),FALSE)=0,"",VLOOKUP($C$15,'CRM Indústrias'!$B:$XFD,MATCH("ADM — e-mail",'CRM Indústrias'!$B$1:$XFD$1,0),FALSE)),"") | H23: =IFERROR(IF(VLOOKUP($C$15,'CRM Indústrias'!$B:$XFD,MATCH("ADM — telefone",'CRM Indústrias'!$B$1:$XFD$1,0),FALSE)=0,"",VLOOKUP($C$15,'CRM Indústrias'!$B:$XFD,MATCH("ADM — telefone",'CRM Indústrias'!$B$1:$XFD$1,0),FALSE)),"")
B24: Gerência | C24: =IFERROR(IF(VLOOKUP($C$15,'CRM Indústrias'!$B:$XFD,MATCH("Gerência — contato",'CRM Indústrias'!$B$1:$XFD$1,0),FALSE)=0,"",VLOOKUP($C$15,'CRM Indústrias'!$B:$XFD,MATCH("Gerência — contato",'CRM Indústrias'!$B$1:$XFD$1,0),FALSE)),"") | E24: =IFERROR(IF(VLOOKUP($C$15,'CRM Indústrias'!$B:$XFD,MATCH("Gerência — e-mail",'CRM Indústrias'!$B$1:$XFD$1,0),FALSE)=0,"",VLOOKUP($C$15,'CRM Indústrias'!$B:$XFD,MATCH("Gerência — e-mail",'CRM Indústrias'!$B$1:$XFD$1,0),FALSE)),"") | H24: =IFERROR(IF(VLOOKUP($C$15,'CRM Indústrias'!$B:$XFD,MATCH("Gerência — telefone",'CRM Indústrias'!$B$1:$XFD$1,0),FALSE)=0,"",VLOOKUP($C$15,'CRM Indústrias'!$B:$XFD,MATCH("Gerência — telefone",'CRM Indústrias'!$B$1:$XFD$1,0),FALSE)),"")
B25: Supervisão | C25: =IFERROR(IF(VLOOKUP($C$15,'CRM Indústrias'!$B:$XFD,MATCH("Supervisão — contato",'CRM Indústrias'!$B$1:$XFD$1,0),FALSE)=0,"",VLOOKUP($C$15,'CRM Indústrias'!$B:$XFD,MATCH("Supervisão — contato",'CRM Indústrias'!$B$1:$XFD$1,0),FALSE)),"") | E25: =IFERROR(IF(VLOOKUP($C$15,'CRM Indústrias'!$B:$XFD,MATCH("Supervisão — e-mail",'CRM Indústrias'!$B$1:$XFD$1,0),FALSE)=0,"",VLOOKUP($C$15,'CRM Indústrias'!$B:$XFD,MATCH("Supervisão — e-mail",'CRM Indústrias'!$B$1:$XFD$1,0),FALSE)),"") | H25: =IFERROR(IF(VLOOKUP($C$15,'CRM Indústrias'!$B:$XFD,MATCH("Supervisão — telefone",'CRM Indústrias'!$B$1:$XFD$1,0),FALSE)=0,"",VLOOKUP($C$15,'CRM Indústrias'!$B:$XFD,MATCH("Supervisão — telefone",'CRM Indústrias'!$B$1:$XFD$1,0),FALSE)),"")
B26: Trocas | C26: =IFERROR(IF(VLOOKUP($C$15,'CRM Indústrias'!$B:$XFD,MATCH("Trocas — contato",'CRM Indústrias'!$B$1:$XFD$1,0),FALSE)=0,"",VLOOKUP($C$15,'CRM Indústrias'!$B:$XFD,MATCH("Trocas — contato",'CRM Indústrias'!$B$1:$XFD$1,0),FALSE)),"") | E26: =IFERROR(IF(VLOOKUP($C$15,'CRM Indústrias'!$B:$XFD,MATCH("Trocas — e-mail",'CRM Indústrias'!$B$1:$XFD$1,0),FALSE)=0,"",VLOOKUP($C$15,'CRM Indústrias'!$B:$XFD,MATCH("Trocas — e-mail",'CRM Indústrias'!$B$1:$XFD$1,0),FALSE)),"") | H26: =IFERROR(IF(VLOOKUP($C$15,'CRM Indústrias'!$B:$XFD,MATCH("Trocas — telefone",'CRM Indústrias'!$B$1:$XFD$1,0),FALSE)=0,"",VLOOKUP($C$15,'CRM Indústrias'!$B:$XFD,MATCH("Trocas — telefone",'CRM Indústrias'!$B$1:$XFD$1,0),FALSE)),"")
B27: NFD | C27: =IFERROR(IF(VLOOKUP($C$15,'CRM Indústrias'!$B:$XFD,MATCH("NFD — contato",'CRM Indústrias'!$B$1:$XFD$1,0),FALSE)=0,"",VLOOKUP($C$15,'CRM Indústrias'!$B:$XFD,MATCH("NFD — contato",'CRM Indústrias'!$B$1:$XFD$1,0),FALSE)),"") | E27: =IFERROR(IF(VLOOKUP($C$15,'CRM Indústrias'!$B:$XFD,MATCH("NFD — e-mail",'CRM Indústrias'!$B$1:$XFD$1,0),FALSE)=0,"",VLOOKUP($C$15,'CRM Indústrias'!$B:$XFD,MATCH("NFD — e-mail",'CRM Indústrias'!$B$1:$XFD$1,0),FALSE)),"") | H27: =IFERROR(IF(VLOOKUP($C$15,'CRM Indústrias'!$B:$XFD,MATCH("NFD — telefone",'CRM Indústrias'!$B$1:$XFD$1,0),FALSE)=0,"",VLOOKUP($C$15,'CRM Indústrias'!$B:$XFD,MATCH("NFD — telefone",'CRM Indústrias'!$B$1:$XFD$1,0),FALSE)),"")
B28: Encarte | C28: =IFERROR(IF(VLOOKUP($C$15,'CRM Indústrias'!$B:$XFD,MATCH("Encarte — contato",'CRM Indústrias'!$B$1:$XFD$1,0),FALSE)=0,"",VLOOKUP($C$15,'CRM Indústrias'!$B:$XFD,MATCH("Encarte — contato",'CRM Indústrias'!$B$1:$XFD$1,0),FALSE)),"") | E28: =IFERROR(IF(VLOOKUP($C$15,'CRM Indústrias'!$B:$XFD,MATCH("Encarte — e-mail",'CRM Indústrias'!$B$1:$XFD$1,0),FALSE)=0,"",VLOOKUP($C$15,'CRM Indústrias'!$B:$XFD,MATCH("Encarte — e-mail",'CRM Indústrias'!$B$1:$XFD$1,0),FALSE)),"") | H28: =IFERROR(IF(VLOOKUP($C$15,'CRM Indústrias'!$B:$XFD,MATCH("Encarte — telefone",'CRM Indústrias'!$B$1:$XFD$1,0),FALSE)=0,"",VLOOKUP($C$15,'CRM Indústrias'!$B:$XFD,MATCH("Encarte — telefone",'CRM Indústrias'!$B$1:$XFD$1,0),FALSE)),"")
B29: Lead time / Obs | C29: =IFERROR(IF(VLOOKUP($C$15,'CRM Indústrias'!$B:$XFD,MATCH("Lead time entrega (dias)",'CRM Indústrias'!$B$1:$XFD$1,0),FALSE)=0,"",VLOOKUP($C$15,'CRM Indústrias'!$B:$XFD,MATCH("Lead time entrega (dias)",'CRM Indústrias'!$B$1:$XFD$1,0),FALSE)),"") | E29: =IFERROR(IF(VLOOKUP($C$15,'CRM Indústrias'!$B:$XFD,MATCH("Observações",'CRM Indústrias'!$B$1:$XFD$1,0),FALSE)=0,"",VLOOKUP($C$15,'CRM Indústrias'!$B:$XFD,MATCH("Observações",'CRM Indústrias'!$B$1:$XFD$1,0),FALSE)),"")
B31: ◆ BUSCAR LOGÍSTICA DE CLIENTE
B33: Cliente: | I33: =HYPERLINK("#'Capa - Dashboard'!C33","🗑 Limpar (clique e tecle Delete)") -> 🗑 Limpar (clique e tecle Delete)
B35: Grupo/Rede: | C35: =IFERROR(IF(VLOOKUP($C$33,'Base de Clientes'!$B:$XFD,MATCH("Grupo/Rede",'Base de Clientes'!$B$1:$XFD$1,0),FALSE)=0,"",VLOOKUP($C$33,'Base de Clientes'!$B:$XFD,MATCH("Grupo/Rede",'Base de Clientes'!$B$1:$XFD$1,0),FALSE)),"")
B36: Canal: | C36: =IFERROR(IF(VLOOKUP($C$33,'Base de Clientes'!$B:$XFD,MATCH("Canal",'Base de Clientes'!$B$1:$XFD$1,0),FALSE)=0,"",VLOOKUP($C$33,'Base de Clientes'!$B:$XFD,MATCH("Canal",'Base de Clientes'!$B$1:$XFD$1,0),FALSE)),"")
B37: Cidade: | C37: =IFERROR(IF(VLOOKUP($C$33,'Base de Clientes'!$B:$XFD,MATCH("Cidade",'Base de Clientes'!$B$1:$XFD$1,0),FALSE)=0,"",VLOOKUP($C$33,'Base de Clientes'!$B:$XFD,MATCH("Cidade",'Base de Clientes'!$B$1:$XFD$1,0),FALSE)),"")
B38: UF: | C38: =IFERROR(IF(VLOOKUP($C$33,'Base de Clientes'!$B:$XFD,MATCH("UF",'Base de Clientes'!$B$1:$XFD$1,0),FALSE)=0,"",VLOOKUP($C$33,'Base de Clientes'!$B:$XFD,MATCH("UF",'Base de Clientes'!$B$1:$XFD$1,0),FALSE)),"")
B39: Telefone ERP: | C39: =IFERROR(IF(VLOOKUP($C$33,'Base de Clientes'!$B:$XFD,MATCH("Telefone",'Base de Clientes'!$B$1:$XFD$1,0),FALSE)=0,"",VLOOKUP($C$33,'Base de Clientes'!$B:$XFD,MATCH("Telefone",'Base de Clientes'!$B$1:$XFD$1,0),FALSE)),"")
B40: Agendamento: | C40: =IFERROR(IF(VLOOKUP($C$33,'Base de Clientes'!$B:$XFD,MATCH("Agendado entrega?",'Base de Clientes'!$B$1:$XFD$1,0),FALSE)=0,"",VLOOKUP($C$33,'Base de Clientes'!$B:$XFD,MATCH("Agendado entrega?",'Base de Clientes'!$B$1:$XFD$1,0),FALSE)),"")
B41: Contato agend: | C41: =IFERROR(IF(VLOOKUP($C$33,'Base de Clientes'!$B:$XFD,MATCH("Contato agendamento",'Base de Clientes'!$B$1:$XFD$1,0),FALSE)=0,"",VLOOKUP($C$33,'Base de Clientes'!$B:$XFD,MATCH("Contato agendamento",'Base de Clientes'!$B$1:$XFD$1,0),FALSE)),"")
B42: E-mail agend: | C42: =IFERROR(IF(VLOOKUP($C$33,'Base de Clientes'!$B:$XFD,MATCH("E-mail agendamento",'Base de Clientes'!$B$1:$XFD$1,0),FALSE)=0,"",VLOOKUP($C$33,'Base de Clientes'!$B:$XFD,MATCH("E-mail agendamento",'Base de Clientes'!$B$1:$XFD$1,0),FALSE)),"")
B43: Tel. agend: | C43: =IFERROR(IF(VLOOKUP($C$33,'Base de Clientes'!$B:$XFD,MATCH("Tel. agendamento",'Base de Clientes'!$B$1:$XFD$1,0),FALSE)=0,"",VLOOKUP($C$33,'Base de Clientes'!$B:$XFD,MATCH("Tel. agendamento",'Base de Clientes'!$B$1:$XFD$1,0),FALSE)),"")
B44: Tel. logística: | C44: =IFERROR(IF(VLOOKUP($C$33,'Base de Clientes'!$B:$XFD,MATCH("Tel. logística",'Base de Clientes'!$B$1:$XFD$1,0),FALSE)=0,"",VLOOKUP($C$33,'Base de Clientes'!$B:$XFD,MATCH("Tel. logística",'Base de Clientes'!$B$1:$XFD$1,0),FALSE)),"")
B45: Resp. logística: | C45: =IFERROR(IF(VLOOKUP($C$33,'Base de Clientes'!$B:$XFD,MATCH("Resp. logística",'Base de Clientes'!$B$1:$XFD$1,0),FALSE)=0,"",VLOOKUP($C$33,'Base de Clientes'!$B:$XFD,MATCH("Resp. logística",'Base de Clientes'!$B$1:$XFD$1,0),FALSE)),"")
B46: Obs logística: | C46: =IFERROR(IF(VLOOKUP($C$33,'Base de Clientes'!$B:$XFD,MATCH("Obs logística",'Base de Clientes'!$B$1:$XFD$1,0),FALSE)=0,"",VLOOKUP($C$33,'Base de Clientes'!$B:$XFD,MATCH("Obs logística",'Base de Clientes'!$B$1:$XFD$1,0),FALSE)),"")
B49: =HYPERLINK("file:///Users/marcelorodrigues/Library/CloudStorage/GoogleDrive-marcelo%403mvrepresentacao.com/Meu%20Drive/3MV/CRM%203MV/_executaveis/Atualizar%20CRM.app","🍎 ATUALIZAR CRM (Mac)") -> 🍎 ATUALIZAR CRM (Mac) | G49: =HYPERLINK("file:///Users/marcelorodrigues/Library/CloudStorage/GoogleDrive-marcelo%403mvrepresentacao.com/Meu%20Drive/3MV/CRM%203MV/_executaveis/Atualizar%20CRM%203MV.bat","🪟 ATUALIZAR CRM (Windows)") -> 🪟 ATUALIZAR CRM (Windows)
B52: ◆ IR PARA
B54: =HYPERLINK("#'CRM Indústrias'!A1","▶ CRM Indústrias") -> ▶ CRM Indústrias | E54: =HYPERLINK("#'Base de Clientes'!A1","▶ Base de Clientes") -> ▶ Base de Clientes | H54: =HYPERLINK("#'Evolução Anual'!A1","▶ Evolução Anual") -> ▶ Evolução Anual
B57: Botões 🍎 (Mac) e 🪟 (Windows) puxam dados novos da API Suas Vendas. Tudo que você preencheu nas colunas amarelas é preservado entre atualizações.

Sheet CRM Indústrias
A1: ID | B1: Indústria | C1: Razão Social | D1: CNPJ | E1: Status ERP | F1: Financeiro — contato | G1: Financeiro — e-mail | H1: Financeiro — telefone | I1: Contas a Pagar — contato | J1: Contas a Pagar — e-mail | K1: Contas a Pagar — telefone | L1: Contas a Receber — contato | M1: Contas a Receber — e-mail | N1: Contas a Receber — telefone | O1: Marketing — contato | P1: Marketing — e-mail | Q1: Marketing — telefone | R1: ADM — contato | S1: ADM — e-mail | T1: ADM — telefone | U1: Gerência — contato | V1: Gerência — e-mail | W1: Gerência — telefone | X1: Supervisão — contato | Y1: Supervisão — e-mail | Z1: Supervisão — telefone | AA1: Trocas — contato | AB1: Trocas — e-mail | AC1: Trocas — telefone | AD1: NFD — contato | AE1: NFD — e-mail | AF1: NFD — telefone | AG1: Encarte — contato | AH1: Encarte — e-mail | AI1: Encarte — telefone | AJ1: Lead time entrega (dias) | AK1: Observações
A2: 893 | B2: BR Spice | C2: BR SPICES INDUSTRIA E COMERCIO DE ALIMENTOS S.A. | D2: 21.418.616/0001-57 | E2: Ativo | F2: Yasmin | G2: yasmin.cerqueira@brspices.com.br | H2: (11) 99282-2460 | L2: Celia | N2: (11) 93908-3486 | R2: Heloísa | S2: admvendas@brspices.com.br | T2: (11) 98918-0943 | U2: Icaro | V2: icaro.pereira@brspices.com.br | W2: (31) 99069-3741
A3: 881 | B3: Casa Madeia | C3: ADEGA CASA DE MADEIRA LTDA | D3: 94.904.133/0001-36 | E3: Ativo | F3: Gesiane | G3: gesiane.morais@famigliavalduga.com.br | H3: (54) 2105-3122 | L3: Cristiane | M3: cristiane.pereira@famigliavalduga.com.br | N3: (54) 99222-4642 | R3: Elisandra | S3: elisandra.aimi@famigliavalduga.com.br | T3: (54) 98128-5310 | U3: Angela | V3: angela.guedes@famigliavalduga.com.br | W3: (54) 98128-5310
A4: 70 | B4: Condor | C4: CONDOR S/A | D4: 86.046.448/0001-61 | E4: Ativo | F4: Oriane | G4: oriane.souza@condor.ind.br | H4: (47) 3631-2420 | R4: Jennifer | S4: jennifer.weber@condor.ind.br | T4: 0800 047 6767 | U4: Rubens Spada | V4: rubens.spada@condor.ind.br | W4: (11) 97016-0425 | AA4: Claudineia | AB4: claudineia.oracz@condor.ind.br | AC4: (47) 99722-1421 | AD4: Claudineia | AE4: claudineia.oracz@condor.ind.br | AF4: (47) 99722-1421
A5: 62 | B5: Dana | C5: PERFUMES DANA DO BRASIL S.A. | D5: 61.105.722/0005-29 | E5: Ativo | F5: Financeiro | G5: contasareceber@danacosmeticos.com.br | H5: (11) 3065-1569; (11) 2842-3245 | I5: Carlos Andre | J5: contasapagar@danacosmeticos.com.br | K5: (11) 2842-3262 | L5: Financeiro | M5: contasareceber@danacosmeticos.com.br | N5: (11) 3065-1569; (11) 2842-3245 | O5: Tiago Espires | P5: tiago.espires@danacosmeticos.com.br | Q5: (11) 99560-0499 | R5: Lais | S5: lais.araujo@danacosmeticos.com.br | T5: (11) 94250-2993 | U5: Rosana (Farma) ; Airton ( Atacado) ; Leonardo (Varejo) | V5: rosana.pereira@danacosmeticos.com.br ; airton.barboza@danacosmeticos.com.br; leonardo.Mesquita@danacosmeticos.com.br | W5: (11) 99559-5338 ; (11) 98188-0172; (31) 99678-4719 | AA5: Bruno Zieri | AB5: bruno.zieri@danacosmeticos.com.br | AC5: (11) 94250-3042 | AD5: Bruno Zieri | AE5: bruno.zieri@danacosmeticos.com.br | AF5: (11) 94250-3042 | AG5: Thiago | AH5: thiago.souza@danacosmeticos.com.br | AI5: (31) 98266-4293
A6: 886 | B6: Domno | C6: DOMNO DO BRASIL INDUSTRIA E COMERCIO DE BEBIDAS LTDA | D6: 09.276.690/0001-80 | E6: Ativo | F6: Gesiane | G6: gesiane.morais@famigliavalduga.com.br | H6: (54) 2105-3122 | L6: Cristiane | M6: cristiane.pereira@famigliavalduga.com.br | N6: (54) 99222-4642 | R6: Elisandra | S6: elisandra.aimi@famigliavalduga.com.br | T6: (54) 98128-5310 | U6: Angela | V6: angela.guedes@famigliavalduga.com.br | W6: (54) 98128-5310
A7: 889 | B7: JACQUES JANINE | C7: BR COSMETIC COMERCIAL LTDA | D7: 17.079.462/0001-49 | E7: Ativo | F7: Elisabete | G7: financeiro2@brcosmetic.com | H7: (11) 97454-1983 | L7: Elisabete | M7: financeiro2@brcosmetic.com | N7: (11) 97454-1983 | O7: Isabella Frediani | P7: design.mkt@brcosmetic.com | Q7: (11) 91594-8226 | R7: Morgana | S7: comercial1@brcosmetic.com | T7: (11) 99835-2076 | X7: Mario | Z7: (11) 97227-2772 | AA7: Gabriel | AB7: devolucao@brcosmetic.com | AC7: (11) 94110-6734 | AD7: Gabriel | AE7: devolucao@brcosmetic.com | AF7: (11) 94110-6734 | AG7: Isabella Frediani | AH7: design.mkt@brcosmetic.com | AI7: (11) 91594-8226
A8: 887 | B8: Kanitz | C8: CDA - DISTRIBUIDORA DE COSMETICOS LTDA. | D8: 06.128.346/0001-56 | E8: Ativo | F8: Edilson | G8: financas@dicoserj.com.br | L8: Edilson | M8: financas@dicoserj.com.br | O8: Lucinea | P8: marketing1@kanitz1900.com.br; marketing2@kanitz1900.com.br | R8: Marcelo | S8: marcelo@kanitz1900.com.br | T8: (21) 98212-7882 | U8: Anderson | V8: anderson@kanitz1900br.onmicrosoft.com | W8: (21) 97232-8314 | AA8: Marcelo | AB8: marcelo@kanitz1900.com.br | AC8: (21) 98212-7882 | AD8: Marcelo | AE8: marcelo@kanitz1900.com.br | AF8: (21) 98212-7882 | AG8: Lucinea | AH8: marketing1@kanitz1900.com.br; marketing2@kanitz1900.com.br
A9: 880 | B9: Leopoldina | C9: CERVEJARIA LEOPOLDINA LTDA | D9: 22.226.696/0001-01 | E9: Ativo | F9: Gesiane | G9: gesiane.morais@famigliavalduga.com.br | H9: (54) 2105-3122 | L9: Cristiane | M9: cristiane.pereira@famigliavalduga.com.br | N9: (54) 99222-4642 | R9: Elisandra | S9: elisandra.aimi@famigliavalduga.com.br | T9: (54) 98128-5310 | U9: Angela | V9: angela.guedes@famigliavalduga.com.br | W9: (54) 98128-5310
A10: 66 | B10: M Dias | C10: M DIAS BRANCO S.A. INDUSTRIA E COMERCIO DE ALIMENTOS | D10: 07.206.816/0042-93 | E10: Ativo
A11: 656 | B11: Melbras | C11: MELBRAS IMPORTADORA E EXPORTADORA AGROINDUSTRIA LTDA | D11: 11.871.823/0001-09 | E11: Ativo | F11: Gisele | G11: financeiro@melbras.com.br | H11: (31) 99622-7104 | L11: Gisele | M11: financeiro@melbras.com.br | N11: (31) 99622-7104 | R11: Leticia | S11: comercial3@melbras.com.br | T11: (31) 9704-3785 | U11: Pablo | V11: pablo.marcio@melbras.com.br | W11: (31) 9987-4726
A12: 709 | B12: Ruby Rose | C12: UNION MEDIC COMERCIO E REPRESENTACAO DE PRODUTOS PARA A SAUDE LTDA | D12: 45.143.429/0001-76 | E12: Ativo
A13: 63 | B13: Semina | C13: SEMINA IND COM LT | D13: 55.163.042/0001-35 | E13: Ativo
A14: 60 | B14: Tia Sonia | C14: ALIMENTOS TIA SONIA LTDA | D14: 08.385.685/0002-24 | E14: Ativo
A15: 869 | B15: Upper | C15: UPPER DOG COMERCIAL LTDA | D15: 22.468.303/0005-08 | E15: Ativo
A16: 882 | B16: Valduga | C16: CASA VALDUGA VINHOS FINOS LTDA | D16: 87.848.180/0001-44 | E16: Ativo | F16: Gesiane | G16: gesiane.morais@famigliavalduga.com.br | H16: (54) 2105-3122 | L16: Cristiane | M16: cristiane.pereira@famigliavalduga.com.br | N16: (54) 99222-4642 | R16: Elisandra | S16: elisandra.aimi@famigliavalduga.com.br | T16: (54) 98128-5310 | U16: Angela | V16: angela.guedes@famigliavalduga.com.br | W16: (54) 98128-5310

Sheet Base de Clientes
A1: ID | B1: Nome fantasia | C1: Grupo/Rede | D1: Canal | E1: Razão social | F1: CNPJ | G1: Cidade | H1: UF | I1: Telefone | J1: E-mail | K1: Pessoa | L1: Status | M1: Comprou 2023-26? | N1: Agendado entrega? | O1: Contato agendamento | P1: E-mail agendamento | Q1: Tel. agendamento | R1: Tel. logística | S1: Resp. logística | T1: Obs logística
A2: 612 | B2: .com açai | C2: — | D2: Açaí | E2: KEILA ALVES RAMALHO 12474483632 | F2: 37.745.450/0001-13 | G2: Governador Valadares | H2: MG | I2: (33) 99148-1635 | J2: keillinha_gv10@hotmail.com | K2: PJ | L2: Inativo | M2: —
A3: 449 | B3: 3MV REPRESENTACOES | C3: — | D3: Representações | E3: 3MV REPRESENTACOES LTDA - ME | F3: 26.424.501/0001-99 | G3: IPATINGA | H3: MG | I3: 31 3822 4687 | J3: marcelo@3mvrepresentacao.com | K3: PJ | L3: Ativo | M3: Sim
A4: 716 | B4: A GRANEL | C4: — | D4: Açaí | E4: LIGEIRO & PIRES PRODUTOS NATURAIS LTDA | F4: 26.822.115/0001-55 | H4: MG | I4: (33) 3322-4000 | J4: MEMCONTABILIDADE@GMAIL.COM | K4: PJ | L4: Inativo | M4: —
A5: 431 | B5: ACAI & CIA | C5: — | D5: Açaí | E5: MGE ACAI E CIA LTDA | F5: 23.913.733/0001-12 | G5: GOVERNADOR VALADARES | H5: MG | I5: (33) 3021-1652 | J5: gustavovazvillela@hotmail.com | K5: PJ | L5: Ativo | M5: Sim
A6: 563 | B6: ACAI CAFE | C6: — | D6: Açaí | E6: DEBORA DE JESUS OLIVEIRA 14037816644 | F6: 36.769.580/0001-23 | G6: Coronel Fabriciano | H6: MG | I6: (31) 98585-6120 | J6: richardson19@globo.com | K6: PJ | L6: Inativo | M6: —
A7: 485 | B7: ACAI CULTURA | C7: — | D7: Açaí | E7: MARIA COSTA SOARES FERRREIRA DE LIMA 30733090630 | F7: 29.865.404/0001-20 | G7: Ipatinga | H7: MG | I7: (31) 3822-3117 | J7: acaicultura@gmail.com | K7: PJ | L7: Inativo | M7: —
A8: 523 | B8: ACAI CULTURA | C8: — | D8: Açaí | E8: ACAICULTURA ALIMENTOS LTDA | F8: 33.269.510/0001-18 | G8: Ipatinga | H8: MG | I8: 31 99400 9797 | J8: thiago.acaicultura@gmail.com | K8: PJ | L8: Inativo | M8: —
A9: 688 | B9: ACAI DICASA | C9: — | D9: Açaí | E9: FABIANO GONCALVES LIBOREIRO 06926987602 | F9: 38.043.185/0001-94 | G9: Governador Valadares | H9: MG | I9: (31) 9546-1035 | J9: FABIANO.LIBOREIRO@YAHOO.COM | K9: PJ | L9: Inativo | M9: —
A10: 507 | B10: ACAI DO ARITANA | C10: — | D10: Açaí | E10: JOAO PAULO SILVA SALES 0218795606 | F10: 32.539.031/0001-01 | G10: Governador Vala | H10: MG | I10: 33 98712 7985 | J10: joao191ja@gmail.com | K10: PJ | L10: Inativo | M10: —
A11: 508 | B11: ACAI DO SIRLEI | C11: — | D11: Açaí | E11: VITORIA FERNANDES SILVA 13021856675 | F11: 33.310.998/0001-80 | G11: Governador Vala | H11: MG | I11: 33 99971 5891 | J11: mais_atacadista@hotmail.com | K11: PJ | L11: Ativo | M11: —
A12: 561 | B12: ACAI DOS VALES | C12: — | D12: Açaí | E12: NILDA SANTOS PEREIRA 09963832636 | F12: 33.956.901/0001-00 | G12: Governador Vala | H12: MG | I12: 33 98727 2889 | J12: arturcastor@hotmail.com | K12: PJ | L12: Ativo | M12: —
A13: 747 | B13: ACAI FRUIT SHOW COLATINA | C13: — | D13: — | E13: ACAI FRUIT SHOW COLATINA LTDA | F13: 44.216.367/0001-12 | G13: COLATINA | H13: ES | I13: (31) 9122-4771 | J13: ANTONIELEBARBOSA1@GMAIL.COM | K13: PJ | L13: Inativo | M13: Sim
A14: 533 | B14: ACAI FRUIT SHOW GV | C14: — | D14: Açaí | E14: ACAI FRUIT SHOW GV LTDA | F14: 31.140.821/0001-57 | G14: GOVERNADOR VALA | H14: MG | I14: 31 9122 4771 | J14: antonielebarbosa1@gmail.com | K14: PJ | L14: Inativo | M14: Sim
A15: 652 | B15: ACAI FRUIT SHOW IPATINGA | C15: — | D15: Açaí | E15: ACAI FRUIT SHOW IPATINGA LTDA | F15: 42.963.776/0001-57 | G15: IPATINGA | H15: MG | I15: (31) 9389-0076 | J15: NANTESGAS@HOTMAIL.COM | K15: PJ | L15: Inativo | M15: Sim
A16: 514 | B16: ACAI FRUIT SHOW TEOFILO OTONI | C16: — | D16: Açaí | E16: ACAI FRUIT SHOW TEOFILO OTONI EIRELI | F16: 28.791.305/0001-88 | G16: TEOFILO OTONI | H16: MG | I16: 31 99122 4771 | J16: acaishow@hotmail.com | K16: PJ | L16: Inativo | M16: Sim
... A29: 530 | B29: AMARETTO IPATINGA | C29: — | D29: Açaí | E29: M E M FILHOS SORVETERIA E CAFETERIA EIRELI | F29: 31.688.061/0001-17 | G29: Ipatinga | H29: MG | I29: 31 98869 8830 | J29: mhmiranda@uol.com.br | K29: PJ | L29: Ativo | M29: —
A30: 705 | B30: AMORIM SUPERMERCADO | C30: — | D30: Supermercado | E30: JTB AMORIM SUPERMERCADOS EIRELI | F30: 03.476.613/0001-98 | H30: MG | I30: (33) 3533-1326 | J30: AMORIMSUPERMERCADO@HOTMAIL.COM.BR | K30: PJ | L30: Inativo | M30: —
A31: 535 | B31: ANDRADE DISTRIBUIDOR | C31: Andrade Distribuidora | D31: Atacarejo | E31: PADARIA E DISTRIBUIDORA CARAVELAS LTDA | F31: 08.056.022/0002-66 | G31: IPATINGA | H31: MG | I31: 31 3825 7407 | J31: distribuidora.andrade@hotmail.com | K31: PJ | L31: Inativo | M31: —
A32: 662 | B32: ANDRADE DISTRIBUIDORA | C32: Andrade Distribuidora | D32: Distribuidor | E32: PADARIA E DISTRIBUIDORA CARAVELAS LTDA | F32: 08.056.022/0001-85 | G32: IPATINGA | H32: MG | I32: (31) 3822-6480 | J32: RRMCONT@UOL.COM.BR | K32: PJ | L32: Inativo | M32: Sim
A33: 517 | B33: ARAUJO E AMORIM | C33: — | D33: Açaí | E33: ARAUJO E AMORIM LTDA | F33: 23.625.927/0001-12 | G33: CARATINGA | H33: MG | I33: 33 99996 6906 | J33: thatianeinaria@hotmail.com | K33: PJ | L33: Inativo | M33: Sim
A34: 358 | B34: ARMAZEM A GRANEL | C34: — | D34: Açaí | E34: HUMBERTO LUCAS BATISTA COSTA 01668515660 | F34: 33.322.542/0001-30 | G34: TIMOTEO | H34: MG | I34: 31 2136 7475 | J34: armazemgranel2020@gmail.com | K34: PJ | L34: Inativo | M34: —
A35: 460 | B35: ARMAZEM DO ACAI | C35: — | D35: Açaí | E35: K V SANTUZZI LANCHONETE | F35: 29.558.496/0001-03 | G35: GOVERNADOR VALA | H35: MG | I35: 33 98749 1638 | J35: armazemdoacaigv@hotmail.com | K35: PJ | L35: Ativo | M35: Sim
A36: 586 | B36: ARMAZEM FIT STORE | C36: — | D36: Açaí | E36: NUTRIR COMERCIO DE ALIMENTOS EIRELI | F36: 33.002.358/0001-02 | G36: IPATINGA | H36: MG | I36: 31 98603 1071 | K36: PJ | L36: Inativo | M36: —
A37: 551 | B37: ARMAZEM SAUDE EM GRA | C37: — | D37: Açaí | E37: CLAUDIA DO CARMO ASSIS 04507372682 | F37: 35.094.535/0001-53 | G37: IPATINGA | H37: MG | I37: 31 99396 9906 | J37: claudiaassis@yahoo.com.br | K37: PJ | L37: Prospectado | M37: —
A38: 416 | B38: ARTE LOCACOES | C38: — | D38: Atacado | E38: ARTE LOCACOES E PROMOCOES LTDA ME | F38: 26.261.453/0001-65 | G38: GOVERNADOR VALA | H38: MG | I38: 31 3424 8000 | J38: majellacosta@gmail.com | K38: PJ | L38: Prospectado | M38: —
A39: 465 | B39: ATACADO SANTA MARIA | C39: — | D39: Atacarejo | E39: ATACADAO SANTA MARIA LTDA | F39: 20.446.391/0001-80 | G39: SANTA MARIA DE | H39: MG | I39: 31 3838 1212 | J39: nfe.atacadaosmi@gmail.com | K39: PJ | L39: Inativo | M39: Sim
A40: 360 | B40: ATACADÃO S. FURTADO 02 | C40: S. Furtado | D40: Atacado | E40: S FURTADO DA SILVA E CIA LTDA | F40: 41.793.050/0003-12 | G40: IPANEMA | H40: MG | I40: 33 3314 1566 | J40: compras@atacadaosfurtado.com.br <compras@atacadaosfurtado.com.br>; | K40: PJ | L40: Ativo | M40: Sim
A41: 432 | B41: ATACAFORTE | C41: Atacaforte | D41: Atacarejo | E41: IRMAOS SOARES LTDA | F41: 20.604.518/0001-41 | G41: GOVERNADOR VALA | H41: MG | I41: 33 3213 5400 | J41: xmlvilaisa@atacaforte.com.br;xml@atacaforte.com.br | K41: PJ | L41: Inativo | M41: —
A42: 434 | B42: ATACAFORTE LJ 02 | C42: Atacaforte | D42: Atacarejo | E42: IRMAOS SOARES LTDA | F42: 20.604.518/0006-56 | G42: GOVERNADOR VALA | H42: MG | I42: 33 3213 5400 | J42: xml@atacaforte.com.br;xmlvilaisa@atacaforte.com.br | K42: PJ | L42: Inativo | M42: —
A43: 435 | B43: ATACAFORTE LJ 03 | C43: Atacaforte | D43: Atacarejo | E43: IRMAOS SOARES LTDA | F43: 20.604.518/0007-37 | G43: GOVERNADOR VALA | H43: MG | I43: 33 3275 1111 | J43: xmlvilaisa@atacaforte.com.br | K43: PJ | L43: Inativo | M43: —
A44: 433 | B44: ATACAFORTE LJ 1 | C44: Atacaforte | D44: Atacarejo | E44: IRMAOS SOARES LTDA | F44: 20.604.518/0002-22 | G44: GOVERNADOR VALA | H44: MG | I44: 33 3213 5400 | J44: xml@atacaforte.com.br | K44: PJ | L44: Inativo | M44: —
A45: 867 | B45: ATACAREJO SAO JOAO - ABRE CAMPO | C45: São João / Gardingo | D45: — | E45: DISTRIBUIDORA IRMAOS GARDINGO IND. COMERCIO E TRANSPORTES LTDA | F45: 18.861.682/0012-45 | G45: Abre Campo | H45: MG | I45: (31) 8421-3403 | J45: CONTABILIDADE@GARDINGO.COM.BR | K45: PJ | L45: Ativo | M45: Sim
A46: 504 | B46: ATACAREJO SÃO JOAO | C46: São João / Gardingo | D46: Atacarejo | E46: DISTRIBUIDORA IRMAOS GARDINGO IND COMERCIO E TRANSPORTES LTDA | F46: 18.861.682/0009-40 | G46: MATIPO | H46: MG | I46: 31 387 31407 | J46: danfe@superirmao.com.br; nfe@gardingo.com.br;gardingo@gardingo.com.br | K46: PJ | L46: Ativo | M46: Sim
A47: 378 | B47: ATENAS | C47: — | D47: Distribuidor | E47: ATENAS DISTRIBUICAO INTELIGENTE LTDA | F47: 31.130.627/0001-90 | G47: CONTAGEM | H47: MG | I47: 31 98805 6364 | J47: logistica@atenasdistribuicao.com.br;jovem@atenasdistribuicao.com.br | K47: PJ | L47: Inativo | M47: —
A48: 685 | B48: BAMBINO | C48: — | D48: — | E48: BAMBINO PRESENTES LTDA | F48: 04.458.732/0001-80 | G48: Manhuaçu | H48: MG | I48: (33) 3331-1033 | J48: BFRANK@SOFT-HARD.COM.BR | K48: PJ | L48: Inativo | M48: —
A49: 885 | B49: BARAO COSMETICOS | C49: — | D49: — | E49: BOTELHO & DAMAZIO COSMETICOS LTDA | F49: 47.350.738/0001-42 | G49: Barão de Cocais | H49: MG | I49: (31) 9872-3923 | K49: PJ | L49: Inativo | M49: —
A50: 840 | B50: BEAUTY CENTER | C50: — | D50: — | E50: ISRAEL SANTOS ROCHA 08371370636 | F50: 45.421.814/0001-38 | G50: Nanuque | H50: MG | I50: (33) 3621-4132 | J50: PONTUALCONTABILIDADEMG@GMAIL.COM | K50: PJ | L50: Inativo | M50: Sim
A51: 638 | B51: BELEZA & CIA | C51: — | D51: Perfumaria | E51: OSEAS OLIVEIRA SILVA & CIA LTDA | F51: 02.698.472/0001-95 | G51: Governador Valadares | H51: MG | K51: PJ | L51: Inativo | M51: Sim
A52: 680 | B52: BELLA CASA | C52: — | D52: Utilidade | E52: E. S. SANTOS UTILIDADES DOMESTICAS | F52: 35.973.397/0001-82 | G52: CARATINGA | H52: MG | I52: (33) 3321-3931 | J52: MARCAGESTAOCONTABIL@GMAIL.COM | K52: PJ | L52: Inativo | M52: —
...

Sheet Evolução Anual
A1: Cliente | B1: Grupo/Rede | C1: Canal | D1: Cidade | E1: UF | F1: 2023 | G1: 2024 | H1: 2025 | I1: 2026 | J1: Total 4 anos | K1: % 24/23 | L1: % 25/24 | M1: % 26/25
A2: 3MV REPRESENTACOES | B2: — | C2: Representações | D2: IPATINGA | E2: MG | F2: 0 | G2: 3992.5898 | H2: 0 | I2: 0 | J2: 3992.5898 | K2: 🆕 novo | L2: -1 | M2: —
A3: ACAI & CIA | B3: — | C3: Açaí | D3: GOVERNADOR VALADARES | E3: MG | F3: 34140.306 | G3: 37812.749 | H3: 36111.976 | I3: 16822.989 | J3: 124888.02 | K3: 0.10756914 | L3: -0.04497882 | M3: -0.53414376
A4: ACAI FRUIT SHOW COLATINA | B4: — | C4: — | D4: COLATINA | E4: ES | F4: 4976.16 | G4: 1658.72 | H4: 0 | I4: 0 | J4: 6634.88 | K4: -0.66666667 | L4: -1 | M4: —
A5: ACAI FRUIT SHOW GV | B5: — | C5: Açaí | D5: GOVERNADOR VALA | E5: MG | F5: 2101.4587 | G5: 272.59878 | H5: 0 | I5: 0 | J5: 2374.0575 | K5: -0.87028116 | L5: -1 | M5: —
A6: ACAI FRUIT SHOW IPATINGA | B6: — | C6: Açaí | D6: IPATINGA | E6: MG | F6: 1848.6928 | G6: 272.59878 | H6: 0 | I6: 0 | J6: 2121.2916 | K6: -0.85254512 | L6: -1 | M6: —
A7: ACAI FRUIT SHOW TEOFILO OTONI | B7: — | C7: Açaí | D7: TEOFILO OTONI | E7: MG | F7: 2797.5542 | G7: 259.59926 | H7: 0 | I7: 0 | J7: 3057.1535 | K7: -0.90720492 | L7: -1 | M7: —
A8: ACAI FRUIT SHOW TIMOTEO | B8: — | C8: Açaí | D8: TIMOTEO | E8: MG | F8: 2061.7929 | G8: 272.59878 | H8: 0 | I8: 0 | J8: 2334.3917 | K8: -0.86778557 | L8: -1 | M8: —
A9: ACAI NO KILO GOVERNADOR VALADARES | B9: — | C9: — | D9: Governador Valadares | E9: MG | F9: 1071.3905 | G9: 960.99814 | H9: 0 | I9: 0 | J9: 2032.3887 | K9: -0.10303655 | L9: -1 | M9: —
A10: ALISSON DE BRITO LITTIG | B10: — | C10: — | D10: Governador Valadares | E10: MG | F10: 1467.9941 | G10: 0 | H10: 0 | I10: 0 | J10: 1467.9941 | K10: -1 | L10: — | M10: —
A11: ALOE BAF | B11: — | C11: Distribuidor | D11: MONTES CLAROS | E11: MG | F11: 837944.95 | G11: 1645728.5 | H11: 1500020.4 | I11: 181545.09 | J11: 4165238.9 | K11: 0.96400547 | L11: -0.088537096 | M11: -0.87897159
A12: ANDRADE DISTRIBUIDORA | B12: Andrade Distribuidora | C12: Distribuidor | D12: IPATINGA | E12: MG | F12: 14356.014 | G12: 25928.647 | H12: 30166.824 | I12: 6618.577 | J12: 77070.062 | K12: 0.8061174 | L12: 0.16345537 | M12: -0.7806008
A13: ARAUJO E AMORIM | B13: — | C13: Açaí | D13: CARATINGA | E13: MG | F13: 673.14506 | G13: 768.26013 | H13: 0 | I13: 0 | J13: 1441.4052 | K13: 0.14129951 | L13: -1 | M13: —
A14: ARMAZEM DO ACAI | B14: — | C14: Açaí | D14: GOVERNADOR VALA | E14: MG | F14: 3171.4112 | G14: 2233.237 | H14: 2877.0239 | I14: 1233.0102 | J14: 9514.6823 | K14: -0.29582232 | L14: 0.2882752 | M14: -0.57142857
A15: ATACADO SANTA MARIA | B15: — | C15: Atacarejo | D15: SANTA MARIA DE | E15: MG | F15: 21884.029 | G15: 42112.801 | H15: 25961.341 | I15: 0 | J15: 89958.171 | K15: 0.92436231 | L15: -0.38352851 | M15: -1
A16: ATACADÃO S. FURTADO 02 | B16: S. Furtado | C16: Atacado | D16: IPANEMA | E16: MG | F16: 168413.17 | G16: 247194.37 | H16: 240077.51 | I16: 24131.084 | J16: 679816.13 | K16: 0.46778527 | L16: -0.028790521 | M16: -0.89948628
A17: ATACAREJO SAMPAIO MANTENOPOLIS | B17: — | C17: Supermercado | D17: Mantenópolis | E17: ES | F17: 143985.72 | G17: 0 | H17: 0 | I17: 0 | J17: 143985.72 | K17: -1 | L17: — | M17: —
A18: ATACAREJO SAO JOAO - ABRE CAMPO | B18: São João / Gardingo | C18: — | D18: Abre Campo | E18: MG | F18: 0 | G18: 1872.6666 | H18: 3115.2703 | I18: 2163.3974 | J18: 7151.3344 | K18: 🆕 novo | L18: 0.66354774 | M18: -0.30555065
A19: ATACAREJO SÃO JOAO | B19: São João / Gardingo | C19: Atacarejo | D19: MATIPO | E19: MG | F19: 6870.7551 | G19: 9845.6677 | H19: 7521.6446 | I19: 2216.359 | J19: 26454.426 | K19: 0.4329819 | L19: -0.23604525 | M19: -0.70533586
A20: BEAUTY CENTER | B20: — | C20: — | D20: Nanuque | E20: MG | F20: 0 | G20: 6647.1411 | H20: 0 | I20: 0 | J20: 6647.1411 | K20: 🆕 novo | L20: -1 | M20: —
A21: BELEZA & CIA | B21: — | C21: Perfumaria | D21: Governador Valadares | E21: MG | F21: 3329.3978 | G21: 0 | H21: 0 | I21: 0 | J21: 3329.3978 | K21: -1 | L21: — | M21: —
A22: BELLACENTER DISTRIBUIDORA | B22: — | C22: Distribuidor | D22: Uberaba | E22: MG | F22: 15060.88 | G22: 0 | H22: 0 | I22: 0 | J22: 15060.88 | K22: -1 | L22: — | M22: —
A23: BIG MAIS SUPERMERCAD | B23: Big Mais | C23: Supermercado | D23: Governador Vala | E23: MG | F23: 462731.89 | G23: 477033.78 | H23: 826779.81 | I23: 246423.43 | J23: 2012968.9 | K23: 0.030907518 | L23: 0.73316826 | M23: -0.70194793
A24: BIG PLUS SUPERMERCADO | B24: — | C24: — | D24: Timóteo | E24: MG | F24: 0 | G24: 1162.0754 | H24: 0 | I24: 0 | J24: 1162.0754 | K24: 🆕 novo | L24: -1 | M24: —
A25: BIOFLORA JANAUBA | B25: — | C25: — | D25: Janaúba | E25: MG | F25: 0 | G25: 0 | H25: 5461.8127 | I25: 0 | J25: 5461.8127 | K25: — | L25: 🆕 novo | M25: -1
A26: BRASIL SUPERMERCADOS CIDADE NOBRE | B26: Supermercado Brasil | C26: Supermercado | D26: IPATINGA | E26: MG | F26: 19324.073 | G26: 24674.992 | H26: 16107.027 | I26: 0 | J26: 60106.092 | K26: 0.27690431 | L26: -0.34723274 | M26: -1
A27: BRASIL SUPERMERCADOS PANORAMA | B27: Supermercado Brasil | C27: Supermercado | D27: IPATINGA | E27: MG | F27: 26092.83 | G27: 17852.688 | H27: 11013.518 | I27: 0 | J27: 54959.035 | K27: -0.31580103 | L27: -0.38308909 | M27: -1
A28: BRASIL SUPERMERCADOS TIMOTEO | B28: Supermercado Brasil | C28: Supermercado | D28: TIMOTEO | E28: MG | F28: 34961.442 | G28: 31148.195 | H28: 18225.334 | I28: 0 | J28: 84334.971 | K28: -0.10907007 | L28: -0.41488315 | M28: -1
A29: C BAESSA DISTRIBUIDORA | B29: — | C29: Atacado | D29: SANTANA DO MANHUACU | E29: MG | F29: 47206.729 | G29: 76115.913 | H29: 0 | I29: 0 | J29: 123322.64 | K29: 0.6123954 | L29: -1 | M29: —
A30: CABELO & CIA CARATINGA | B30: — | C30: — | D30: Caratinga | E30: MG | F30: 2972.408 | G30: 8271.4643 | H30: 0 | I30: 0 | J30: 11243.872 | K30: 1.7827486 | L30: -1 | M30: —
A31: CABELO & CIA PRODUTOS PARA CABELOS EIRELI | B31: — | C31: Perfumaria | D31: GOVERNADOR VALADARES | E31: MG | F31: 3755.4457 | G31: 4453.8347 | H31: 6990.6837 | I31: 0 | J31: 15199.964 | K31: 0.18596699 | L31: 0.5695876 | M31: -1
A32: CABELO & PELE | B32: — | C32: Perfumaria | D32: Governador Valadares | E32: MG | F32: 8068.3901 | G32: 4218.9298 | H32: 0 | I32: 0 | J32: 12287.32 | K32: -0.47710389 | L32: -1 | M32: —
A33: CASA ALADIM BA | B33: — | C33: Distribuidor | D33: Feira de Santana | E33: BA | F33: 8863488.5 | G33: 6680272.2 | H33: 2737709.5 | I33: 407506.12 | J33: 18688976 | K33: -0.24631569 | L33: -0.59017995 | M33: -0.85115071
A34: CASA ALADIM BETIM MG | B34: — | C34: — | D34: Betim | E34: MG | F34: 4447040.7 | G34: 4876191 | H34: 1029083.5 | I34: 552701.64 | J34: 10905017 | K34: 0.096502446 | L34: -0.7889575 | M34: -0.46291858
A35: CASA ALADIM MG | B35: — | C35: Distribuidor | D35: TEÓFILO OTONI | E35: MG | F35: 709262.99 | G35: 695847.86 | H35: 185185.98 | I35: 0 | J35: 1590296.8 | K35: -0.018914174 | L35: -0.73387001 | M35: -1
A36: CASA DO BISCOITO | B36: — | C36: — | D36: Manhuaçu | E36: MG | F36: 5530.1242 | G36: 0 | H36: 0 | I36: 0 | J36: 5530.1242 | K36: -1 | L36: — | M36: —
A37: CASA DO BISCOITO DE CARATINGA | B37: — | C37: — | D37: Caratinga | E37: MG | F37: 5530.1242 | G37: 0 | H37: 0 | I37: 0 | J37: 5530.1242 | K37: -1 | L37: — | M37: —
A38: CASA DO CABELEIREIRO DE CARATINGA | B38: — | C38: — | D38: Caratinga | E38: MG | F38: 0 | G38: 4190.3126 | H38: 0 | I38: 0 | J38: 4190.3126 | K38: 🆕 novo | L38: -1 | M38: —
A39: CASA PINHO | B39: — | C39: — | D39: Sabinópolis | E39: MG | F39: 4793.8662 | G39: 0 | H39: 0 | I39: 0 | J39: 4793.8662 | K39: -1 | L39: — | M39: —
A40: CD GARCIA JARDIM PANORAMA | B40: Garcia Supermercados | C40: — | D40: Ipatinga | E40: MG | F40: 0 | G40: 0 | H40: 151605.18 | I40: 0 | J40: 151605.18 | K40: — | L40: 🆕 novo | M40: -1
...

Sheet Contatos Adicionais
A1: Indústria | B1: Setor | C1: Contato | D1: Cargo / Função | E1: E-mail | F1: Telefone / Celular | G1: Observações

Sheet _Listas
A1: Setores | B1: Indústrias | C1: Clientes
A2: Financeiro | B2: BR Spice | C2: .com açai
A3: Contas a Pagar | B3: Casa Madeia | C3: 3MV REPRESENTACOES
A4: Contas a Receber | B4: Condor | C4: A GRANEL
A5: Marketing | B5: Dana | C5: ACAI & CIA
A6: ADM | B6: Domno | C6: ACAI CAFE
A7: Gerência | B7: JACQUES JANINE | C7: ACAI CULTURA
A8: Supervisão | B8: Kanitz | C8: ACAI DICASA
A9: Trocas | B9: Leopoldina | C9: ACAI DO ARITANA
A10: NFD | B10: M Dias | C10: ACAI DO SIRLEI
A11: Encarte | B11: Melbras | C11: ACAI DOS VALES
B12: Ruby Rose | C12: ACAI FRUIT SHOW COLATINA
B13: Semina | C13: ACAI FRUIT SHOW GV
B14: Tia Sonia | C14: ACAI FRUIT SHOW IPATINGA
B15: Upper | C15: ACAI FRUIT SHOW TEOFILO OTONI
B16: Valduga | C16: ACAI FRUIT SHOW TIMOTEO
C17: ACAI FRUIT SHOW UBERLANDIA
C18: ACAI IPITANGA
C19: ACAI MIX BRASIL
C20: ACAI NO KILO GOVERNADOR VALADARES
C21: ACAI VIP
C22: ACAIDERA MIX
C23: ALCATEIA HAMBURGUERI
C24: ALIMENTOS NOBRE
C25: ALISSON DE BRITO LITTIG
C26: ALOE BAF
C27: ALVIM DISTRIBUIDORA
C28: AMARETTO IPATINGA
... C481: ZARB DISTRIBUIDORA
